Workbook
Name PLANTING: 'Planting GPS Points'!$B$5:$AL$282

Sheet README
B2: This spreadsheet is a copy of the eelgrass restoration spreadsheet that resides here:
B4: K:\projects\Eelgrass_Restoration\MATRIX
B7: 45923 | C7: This copy was made of the source file when it had a date stamp of 9/16/2025 4:15pm
B9: 46054 | C9: File edited as part of data update.

Sheet Data_dictionary
A1: WORKSHEET | B1: HEADER | C1: SUB-HEADING | D1: DESCRIPTION | E1: NOTES
A2: Assessments | B2: DATE | C2: (YYYY-MM-DD) | D2: date of site assessment activity
A3: Assessments | B3: PROJECT | D3: name of project
A4: Assessments | B4: SITE | D4: general area or embayment that the site is located
A5: Assessments | B5: SITE NAME | D5: characteristics that identify specific planting. Information includes: site location, who did it, where within site, type, year
A6: Assessments | B6: SITE TYPE | C6: (restoration, existing) | D6: is the assessment to scope out a potential restoration site or to check on existing eelgrass conditions (e.g., shoot density, depth range, substrate type) in an area?
A7: Assessments | B7: ASSESSMENT TYPE | C7: (point, drift) | D7: is the assessment a single point visit or a drift with a drift start point (Point) and drift end point (Drift Finish)?
A8: Assessments | B8: ASSESSMENT METHOD | C8: (surface, camera, diver) | D8: is the point assessment taken from the surface of a research vessel, using a camera, or using divers
A9: Assessments | B9: POINT - Latitude | C9: (dec deg) | D9: latitude in decimal degrees of point assessment or if Assessment type is drift, start of drift assessment, precision to 0.00001 degrees
A10: Assessments | B10: POINT - Longitude | C10: (dec deg) | D10: longitude in decimal degrees of point assessment or if Assessment type is drift, start of drift assessment, precision to 0.00001 degrees
A11: Assessments | B11: DRIFT FINISH - Latitude | C11: (dec deg) | D11: If drift assessment then end of drift latitude in decimal degrees, precision to 0.00001 degrees
A12: Assessments | B12: DRIFT FINISH - Longitude | C12: (dec deg) | D12: If drift assessment then end of drift longitude in decimal degrees, precision to 0.00001 degrees
A13: Assessments | B13: DATUM | C13: (WGS84, NAVD83) | D13: geographic datum of the GPS that collected the lat/long data
A14: Assessments | B14: ELEVATION | C14: (m, MLLW) | D14: corrected elevation based on depth and tides in meters relative to MLLW
A15: Assessments | B15: WATER | C15: (clear, turbid) | D15: condition of water
A16: Assessments | B16: SEDIMENT | C16: (mud/silt, fine sand, coarse sand, cobble, bedrock) | D16: sediment type
A17: Assessments | B17: EELGRASS | C17: (absent, sparse, dense) | D17: condition of eelgrass (absent, sparse, dense, unknown)
A18: Assessments | B18: ASSESSMENT STATUS | C18: (poor, moderate, good, na) | D18: assessment for restoration potential; the "na" category is only for restoration Site Types that had eelgrass present
A19: Assessments | B19: NOTES | D19: additional notes
A20: Assessments | B20: ANCILLARY DATA | D20: filename of field notes or report that further document assessment
A22: Planting | B22: SITE LOCATION | D22: general area or embayment that the site is located
A23: Planting | B23: SITE NAME | D23: characteristics that identify specific planting. Information includes: site location, who did it, where within site, type, year
A24: Planting | B24: YEAR | D24: year transplant or site assessment activity occurred
A25: Planting | B25: HISTORICAL PRESENCE | C25: (citation) | D25: citation of document that shows eelgrass historically grew at site or personal observation
A26: Planting | B26: DATA TYPE | C26: (point, polygon, transect) | D26: lat/long coordinate represents point data or multiple coordinates represent a polygon or transect
A27: Planting | B27: WATER BODY | D27: body of water where site resides
A28: Planting | B28: SVMP REGION | D28: Submerged Vegetation Monitoring Program region site is located
A29: Planting | B29: PROJECT NAME | D29: Title of funding source proposal
A30: Planting | B30: FUNDING SOURCE | D30: Organization that has contracted DNR
A31: Planting | B31: FUNDING SOURCE PROGRAM | D31: Program that is providing funding
A32: Planting | B32: CONTRACT 1 | C32: (b/w funding source & DNR) | D32: funding source contract # for contract between DNR and funding source
A33: Planting | B33: CONTRACT 1 | C33: (DNR contract #) | D33: DNR contract # for contract between DNR and funding source
A34: Planting | B34: CONTRACT 2 | C34: (b/w DNR & contractor) | D34: contractor DNR hired to complete project
A35: Planting | B35: CONTRACT 2 | C35: (DNR contract #) | D35: DNR contract # for agreement between DNR and contractor
A36: Planting | B36: CITATION | D36: citation of document data are presented in
A37: Planting | B37: ACTIVITY TYPE | C37: (test planting, large-scale planting) | D37: Type of restoration activity performed at site
A38: Planting | B38: ACTIVITY FILTER | C38: (test planting, large-scale planting) | D38: Type of restoration activity performed at site used to quanitify number of test transplant and large-scale transplant. For example, Activity Type is only listed once for a site with multiple corner points (polygon).
A39: Planting | B39: PLANTING DATE | C39: (YYYY-MM-DD) | D39: date of eelgrass restoration activity
A40: Planting | B40: LATITUDE | C40: (dec deg) | D40: latitude in decimal degrees, precision to 0.00001 degrees
A41: Planting | B41: LONGITUDE | C41: (dec deg) | D41: longitude in decimal degrees, precision to 0.00001 degrees
...

Sheet Assessments
A1: DATE | B1: PROJECT | C1: SITE | D1: SITE NAME | E1: SITE TYPE | F1: ASSESSMENT TYPE | G1: ASSESSMENT METHOD | H1: POINT - Latitude | I1: POINT - Longitude | J1: DRIFT FINISH - Latitude | K1: DRIFT FINISH - Longitude | L1: DATUM | M1: ELEVATION | N1: WATER | O1: SEDIMENT | P1: EELGRASS | Q1: ASSESSMENT STATUS | R1: NOTES | S1: ANCILLARY DATA
A2: (YYYY-MM-DD) | E2: (restoration, existing) | F2: (point, drift) | G2: (surface, camera, diver, sounder) | H2: (dec deg) | I2: (dec deg) | J2: (dec deg) | K2: (dec deg) | L2: (WGS84, NAD83) | M2: (m, MLLW) | N2: (clear, turbid) | O2: (mud/silt, fine sand, coarse sand, cobble, bedrock) | P2: (absent, sparse, present, dense) | Q2: (poor, moderate, good, na)
A3: 41215 | B3: DNR 2020 | C3: NE Squamish Harbor | D3: NE Squamish Harbor-PNNL-2012 Site Assessment point | E3: restoration | F3: point | G3: camera | H3: 47.86305 | I3: -122.69147 | L3: WGS84 | M3: -1.7 | N3: clear | O3: sand | P3: present | Q3: na | R3: zm patch | S3: 2012_1102to1113_EelgrassSiteAssessments.pdf
A4: 41215 | B4: DNR 2020 | C4: NE Squamish Harbor | D4: NE Squamish Harbor-PNNL-2012 Site Assessment track | E4: restoration | F4: drift | G4: camera | H4: 47.86237 | I4: -122.69047 | J4: 47.86527 | K4: -122.68908 | L4: WGS84 | M4: -3.4 | N4: clear | O4: sand | P4: sparse | Q4: na | R4: elevation range from -0.8m to -7.0m, some cobble and some fines mixed with sand, some zm shoots separated from the patch, many houses w/ docks on shoreline possible increased boat traffic in summer | S4: 2012_1102to1113_EelgrassSiteAssessments.pdf
A5: 41215 | B5: DNR 2020 | C5: Port Gamble | D5: Port Gamble-PNNL-2012 Site Assessment point | E5: restoration | F5: point | G5: camera | H5: 47.823333 | I5: -122.57913 | L5: WGS84 | M5: -8.2 | N5: clear | O5: mud/silt | P5: absent | Q5: poor | R5: very muddy | S5: 2012_1102to1113_EelgrassSiteAssessments.pdf
A6: 41215 | B6: DNR 2020 | C6: Port Gamble | D6: Port Gamble-PNNL-2012 Site Assessment track | E6: restoration | F6: drift | G6: camera | H6: 47.822717 | I6: -122.58055 | J6: 47.820717 | K6: -122.5799 | L6: WGS84 | M6: -3.2 | N6: clear | O6: mud/silt | P6: absent | Q6: poor | R6: elevation range from -2.5m to -3.5m, red/brown algae clumps and sand dollars, sediment mounds (worms?) | S6: 2012_1102to1113_EelgrassSiteAssessments.pdf
A7: 41215 | B7: DNR 2020 | C7: Port Gamble | D7: Port Gamble-PNNL-2012 Site Assessment zigzag | E7: restoration | F7: drift | G7: camera | H7: 47.820717 | I7: -122.5799 | J7: 47.822733 | K7: -122.57442 | L7: WGS84 | M7: -5.2 | N7: clear | O7: mud/silt | P7: absent | Q7: poor | R7: elevation range from -2.5m to -7m, started zigzag pattern E/SE along base of bay, more fines, red/brown algae clumps, | S7: 2012_1102to1113_EelgrassSiteAssessments.pdf
A8: 41215 | B8: DNR 2020 | C8: Squamish Bay Shoal | D8: Suquamish Bay Shoal-PNNL-2012 Site Assessment point 1 | E8: restoration | F8: point | G8: camera | H8: 47.8486 | I8: -122.6739 | L8: WGS84 | M8: -2.2 | N8: clear | O8: cobble | P8: present | Q8: na | R8: small patch near another small patch | S8: 2012_1102to1113_EelgrassSiteAssessments.pdf
A9: 41215 | B9: DNR 2020 | C9: Squamish Bay Shoal | D9: Suquamish Bay Shoal-PNNL-2012 Site Assessment track 1 | E9: restoration | F9: drift | G9: camera | H9: =47+(51.258/60) -> 47.8543 | I9: =-1*(122+(40.447/60)) -> -122.67412 | J9: =47+(51.345/60) -> 47.85575 | K9: =-1*(122+(40.297/60)) -> -122.67162 | L9: WGS84 | M9: -3.6 | N9: clear | O9: sand, cobble | P9: dense | Q9: na | R9: elevation range from -2.5m to -5.9m, eelgrass present with some mixed kelp, zm ends approx -4.4m | S9: 2012_1102to1113_EelgrassSiteAssessments.pdf, video file 20161102-110155
A10: 41215 | B10: DNR 2020 | C10: Squamish Bay Shoal | D10: Suquamish Bay Shoal-PNNL-2012 Site Assessment track 2 | E10: restoration | F10: drift | G10: camera | H10: 47.8471 | I10: -122.67552 | J10: 47.848733 | K10: -122.67398 | L10: WGS84 | M10: -4.7 | N10: clear | O10: cobble | P10: sparse | Q10: na | R10: elevation range from -2.7m to -8.9m, some zm patches with some kelp | S10: 2012_1102to1113_EelgrassSiteAssessments.pdf
A11: 41220 | B11: DNR 2020 | C11: Fey Bainbridge | D11: Fey Bainbridge-PNNL-2012 Site Assessment | E11: restoration | F11: drift | G11: camera | H11: 47.689933 | I11: -122.50038 | J11: 47.690583 | K11: -122.5013 | L11: WGS84 | M11: -1.5 | N11: clear | O11: sand | P11: dense | Q11: na | R11: elevation range from 0.4m to -3.5m, large thick meadow with small patches nearby | S11: 2012_1102to1113_EelgrassSiteAssessments.pdf
A12: 41220 | B12: DNR 2020 | C12: Liberty Bay | D12: Liberty Bay "why not"-PNNL-2012 Site Assessment | E12: restoration | F12: drift | G12: camera | H12: 47.705867 | I12: -122.60947 | J12: 47.707333 | K12: -122.61253 | L12: WGS84 | M12: -1.7 | N12: clear | O12: sand | P12: absent | Q12: poor | R12: elevation range from -4.4m to -0.1m, substrate sand to more course, not promising by worth test planting if already planting nearby | S12: 2012_1102to1113_EelgrassSiteAssessments.pdf
A13: 41220 | B13: DNR 2020 | C13: Liberty Bay | D13: Liberty Bay mouth-PNNL-2012 Site Assessment point | E13: restoration | F13: point | G13: camera | H13: 47.692033 | I13: -122.59348 | L13: WGS84 | M13: -0.2 | N13: clear | O13: sand | P13: absent | Q13: moderate | R13: definite shipt in substrate from sand to cobble and lots of shells | S13: 2012_1102to1113_EelgrassSiteAssessments.pdf
A14: 41220 | B14: DNR 2020 | C14: Liberty Bay | D14: Liberty Bay mouth-PNNL-2012 Site Assessment track 1 | E14: restoration | F14: drift | G14: camera | H14: 47.690733 | I14: -122.59237 | J14: 47.692333 | K14: -122.59368 | L14: WGS84 | M14: -1.6 | N14: clear | O14: sand | P14: absent | Q14: moderate | R14: elevation range from -1.6m to -3.1m, lots of kelp with sand and ulva | S14: 2012_1102to1113_EelgrassSiteAssessments.pdf
A15: 41220 | B15: DNR 2020 | C15: Liberty Bay | D15: Liberty Bay mouth-PNNL-2012 Site Assessment track 2 | E15: restoration | F15: drift | G15: camera | H15: 47.692367 | I15: -122.5949 | J15: 47.69365 | K15: -122.59627 | L15: WGS84 | M15: -1.2 | N15: clear | O15: sand | P15: absent | Q15: moderate | R15: elevation range from -0.2m to -1.2m, many tube worms visible out of substrate, might be good spot between upper kelp band and shallower shell/cobble band, not sure why zm not here unless there is too much exposure, worth revisiting | S15: 2012_1102to1113_EelgrassSiteAssessments.pdf
A16: 41220 | B16: DNR 2020 | C16: Miller Bay | D16: Miller Bay-PNNL-2012 Site Assessment point | E16: restoration | F16: point | G16: camera | H16: 47.74505 | I16: -122.52948 | L16: WGS84 | M16: -1.9 | N16: clear | O16: sand | P16: dense | Q16: na | R16: elevation range from 0.6m to -5.8m, drifting NNW, short patchy zm, substrate has wave ripples, moorings and docks along shore out to ~250m from shoreline | S16: 2012_1102to1113_EelgrassSiteAssessments.pdf
A17: 41220 | B17: DNR 2020 | C17: Miller Bay | D17: Miller Bay-PNNL-2012 Site Assessment track 1 | E17: restoration | F17: drift | G17: camera | H17: 47.7447 | I17: -122.53487 | J17: 47.746167 | K17: -122.5358 | L17: WGS84 | M17: 0.4 | N17: clear | O17: sand | P17: dense | Q17: na | R17: elevation range from 0.5m to 0.2m, drifting NNW, small tufty patches of grass | S17: 2012_1102to1113_EelgrassSiteAssessments.pdf
A18: 41220 | B18: DNR 2020 | C18: Miller Bay | D18: Miller Bay-PNNL-2012 Site Assessment track 2 | E18: restoration | F18: drift | G18: camera | H18: 47.7431 | I18: -122.54483 | J18: 47.74345 | K18: -122.5469 | L18: WGS84 | M18: -2 | N18: clear | O18: sand | P18: dense | Q18: na | R18: elevation range from -1.6m to -2.2m, near mouth of miller bay, grass in channel, very healthy | S18: 2012_1102to1113_EelgrassSiteAssessments.pdf
A19: 41221 | B19: DNR 2020 | C19: Anderson Island | D19: Anderson Island, Amsterdam Bay- PNNL-2012 Site Assessment | E19: restoration | F19: drift | G19: camera | H19: 47.158367 | I19: -122.72148 | J19: 47.158867 | K19: -122.72258 | L19: WGS84 | M19: -0.8 | N19: clear | O19: sand | P19: absent | Q19: good | R19: some algae, appears settled, appears to be a good site for planting, only concern is depth and recreational dock | S19: 2012_1102to1113_EelgrassSiteAssessments.pdf
A20: 41221 | B20: DNR 2020 | C20: Anderson Island | D20: Anderson Island, outside Amsterdam Bay-PNNL-2012 Site Assessment | E20: restoration | F20: drift | G20: camera | H20: 47.161467 | I20: -122.72612 | J20: 47.1623 | K20: -122.72808 | L20: WGS84 | M20: -2.7 | N20: turbid | O20: sand | P20: absent | Q20: moderate | R20: elevation range from -0.9m to -3.5m, green and red algae patches, "turfing" red algae, open sand with little vegetation | S20: 2012_1102to1113_EelgrassSiteAssessments.pdf
A21: 41221 | B21: DNR 2020 | C21: Dickerson Point | D21: Dickerson Point-PNNL-2012 Site Assessment | E21: restoration | F21: drift | G21: camera | H21: 47.166717 | I21: -122.84873 | J21: 47.15995 | K21: -122.84717 | L21: WGS84 | M21: -1 | N21: clear | O21: sand | P21: absent | Q21: moderate | R21: elevation range from 0.5m to -4.7m, sand dollars, sand not veg, patches of red algae, substrate and slope good, unsre of target depth, moorings could indicate heavy summer traffic | S21: 2012_1102to1113_EelgrassSiteAssessments.pdf
A22: 41221 | B22: DNR 2020 | C22: Dover Point | D22: Dover Point-PNNL-2012 Site Assessment | E22: restoration | F22: drift | G22: camera | H22: 47.145383 | I22: -122.89117 | J22: 47.146083 | K22: -122.8928 | L22: WGS84 | M22: -0.7 | N22: turbid | O22: sand | P22: absent | Q22: poor | R22: elevation range from 0.9m to -3.6m, substrate and grade look good but don't know appropriate target depth at this location, suspect it gets storm exposure | S22: 2012_1102to1113_EelgrassSiteAssessments.pdf
A23: 41221 | B23: DNR 2020 | C23: Joemma State Park | D23: Joemma State Park, Case Inlet-PNNL-2012 Site Assessment | E23: restoration | F23: drift | G23: camera | H23: 47.22145 | I23: -122.80993 | J23: 47.223867 | K23: -122.81177 | L23: WGS84 | M23: -0.9 | N23: clear | O23: sand, cobble | P23: absent | Q23: good | R23: elevation range from 0.3m to -2.3m, substrate varies from sand to cobble, drift was zig zag pattern, some algae near pilings, state park has mooring and docks, potential if kept away from moorings and docks. Will probably be a narrow fringe, perhaps test planting should be lon and narrow band perpendicular to shore | S23: 2012_1102to1113_EelgrassSiteAssessments.pdf
A24: 41221 | B24: DNR 2020 | C24: McMicken and Harstine Island | D24: McMicken and Harstine Island-PNNL-2012 Site Assessment drift 1 | E24: restoration | F24: drift | G24: camera | H24: 47.245233 | I24: -122.8649 | J24: 47.242783 | K24: -122.86483 | L24: WGS84 | M24: -0.3 | N24: clear | O24: sand | P24: absent | Q24: moderate | R24: elevation range from 0.0m to -0.7m, lots of ulva and sand, may be an approriate site for test plant but not first choice because of ulva and possible exposure | S24: 2012_1102to1113_EelgrassSiteAssessments.pdf
A25: 41221 | B25: DNR 2020 | C25: McMicken and Harstine Island | D25: McMicken and Harstine Island-PNNL-2012 Site Assessment drift 2 | E25: restoration | F25: drift | G25: camera | H25: 47.246983 | I25: -122.86718 | J25: 47.246067 | K25: -122.86803 | L25: WGS84 | M25: -1.6 | N25: clear | O25: sand | P25: absent | Q25: poor | R25: elevation range from -0.2m to -3.6m, possible rocky under sand, kelp and lots of ulva | S25: 2012_1102to1113_EelgrassSiteAssessments.pdf
A26: 41221 | B26: DNR 2020 | C26: Anderson Island | D26: NE Anderson Island-PNNL-2012 Site Assessment | E26: restoration | F26: drift | G26: camera | H26: 47.181433 | I26: -122.68098 | J26: 47.181333 | K26: -122.6816 | L26: WGS84 | M26: -1.6 | N26: clear | O26: cobble | P26: absent | Q26: poor | R26: elevation range from -0.1m to -3.2m, due to substrate and fetch from nw, high exposure, not a good candidate site | S26: 2012_1102to1113_EelgrassSiteAssessments.pdf
A27: 41221 | B27: DNR 2020 | C27: Anderson Island | D27: NW Anderson Island (CPS1285)-PNNL-2012 Site Assessment | E27: restoration | F27: drift | G27: camera | H27: 47.178683 | I27: -122.7218 | J27: 47.179983 | K27: -122.72 | L27: WGS84 | M27: -2.2 | N27: clear | O27: sand | P27: absent | Q27: moderate | R27: elevation range from 0.2m to -4.8m, could grow a narrow fringe here | S27: 2012_1102to1113_EelgrassSiteAssessments.pdf
A28: 41225 | B28: DNR 2020 | C28: Crescent Harbor | D28: Crescent Harbor-PNNL-2012 Site Assessment | E28: restoration | F28: drift | G28: camera | H28: 48.293567 | I28: -122.61293 | J28: 48.29525 | K28: -122.61338 | L28: WGS84 | M28: -1.3 | N28: turbid | O28: sand | P28: sparse | Q28: na | R28: elevation range from 0.5m to -3.4m, extensive sparse, thin density meadow of zm | S28: 2012_1102to1113_EelgrassSiteAssessments.pdf
... A34: 41226 | B34: DNR 2020 | C34: Decator Island | D34: Decator Island-PNNL-2012 Site Assessment | E34: restoration | F34: drift | G34: camera | H34: 48.496717 | I34: -122.8216 | J34: 48.49795 | K34: -122.82053 | L34: WGS84 | M34: -4 | N34: turbid | O34: mud/silt, fine sand | P34: present | Q34: na | R34: elevation range from -0.3m to -6.7m, very muddy, with sand, shallow zm patchy but can be dense | S34: 2012_1102to1113_EelgrassSiteAssessments.pdf
A35: 41226 | B35: DNR 2020 | C35: Decator Island | D35: Decator Island-PNNL-2012 Site Assessment point 1 | E35: restoration | F35: point | G35: camera | H35: 48.497233 | I35: -122.8187 | L35: WGS84 | M35: -1.1 | N35: turbid | O35: mud/silt, fine sand | P35: present | Q35: na | R35: small thick patch of zm, | S35: 2012_1102to1113_EelgrassSiteAssessments.pdf
A36: 41226 | B36: DNR 2020 | C36: Decator Island | D36: Decator Island-PNNL-2012 Site Assessment point 2 | E36: restoration | F36: point | G36: camera | H36: 48.498133 | I36: -122.81757 | L36: WGS84 | M36: 0 | N36: turbid | O36: mud/silt, fine sand | P36: present | Q36: na | R36: large healthy meadow of zm, quite dense | S36: 2012_1102to1113_EelgrassSiteAssessments.pdf
A37: 41226 | B37: DNR 2020 | C37: Guemes Island - east | D37: Guemes Island - east -PNNL-2012 Site Assessment point | E37: restoration | F37: point | G37: camera | H37: 48.577983 | I37: -122.63238 | L37: WGS84 | M37: -2.9 | N37: turbid | O37: sand | P37: present | Q37: na | R37: zm habitat and grass look healthy, thin but long shoots among kelp and some algae | S37: 2012_1102to1113_EelgrassSiteAssessments.pdf
A38: 41226 | B38: DNR 2020 | C38: Guemes Island - west | D38: Guemes Island - west -PNNL-2012 Site Assessment drift | E38: restoration | F38: drift | G38: camera | H38: 48.55985 | I38: -122.64855 | J38: 48.5618 | K38: -122.64605 | L38: WGS84 | M38: -3.3 | N38: turbid | O38: sand, coarse sand | P38: sparse | Q38: na | R38: elevation range from -1.6m to -5.8m, habitat looks healthy, zm is a wide swath | S38: 2012_1102to1113_EelgrassSiteAssessments.pdf
A39: 41226 | B39: DNR 2020 | C39: Orcas Island | D39: Orcas Island-PNNL-2012 Site Assessment drift | E39: restoration | F39: drift | G39: camera | H39: 48.6892 | I39: -122.89072 | J39: 48.692217 | K39: -122.88973 | L39: WGS84 | M39: -2 | N39: clear | O39: sand | P39: dense | Q39: na | R39: lots of zm, some with algae, all very healthy | S39: 2012_1102to1113_EelgrassSiteAssessments.pdf
A40: 41226 | B40: DNR 2020 | C40: Orcas Island | D40: Orcas Island-PNNL-2012 Site Assessment point | E40: restoration | F40: point | G40: camera | H40: 48.6902 | I40: -122.8906 | L40: WGS84 | M40: -1.8 | N40: clear | O40: sand | P40: dense | Q40: na | R40: zm bed | S40: 2012_1102to1113_EelgrassSiteAssessments.pdf
A41: 41968 | B41: Eelgrass Restoration in PS | C41: Key Peninsula-east | D41: Key Peninsula-east-PNNL-2014 Site Assessment point 1 | E41: restoration | F41: point | G41: camera | H41: 47.273228 | I41: -122.75415 | L41: WGS84 | M41: -1.524 | O41: sand | P41: present | Q41: na | R41: sandy w/ eelgrass. Eelgrass present at elevations -0.9, -1.9, -0.1 but eelgrass is patchy. | S41: 2014_1125_S Sound out of Home.pdf
A42: 41968 | B42: Eelgrass Restoration in PS | C42: Key Peninsula-east | D42: Key Peninsula-east-PNNL-2014 Site Assessment point 10 | E42: restoration | F42: point | G42: camera | H42: 47.25605 | I42: -122.73737 | L42: WGS84 | M42: -1.28016 | O42: cobble | P42: absent | Q42: poor | R42: cobble | S42: 2014_1125_S Sound out of Home.pdf
A43: 41968 | B43: Eelgrass Restoration in PS | C43: Key Peninsula-east | D43: Key Peninsula-east-PNNL-2014 Site Assessment point 11 | E43: restoration | F43: point | G43: camera | H43: 47.254883 | I43: -122.73687 | L43: WGS84 | M43: -0.70104 | O43: sand | P43: absent | Q43: good | R43: sandy, good potential | S43: 2014_1125_S Sound out of Home.pdf
A44: 41968 | B44: Eelgrass Restoration in PS | C44: Key Peninsula-east | D44: Key Peninsula-east-PNNL-2014 Site Assessment point 12 | E44: restoration | F44: point | G44: camera | H44: 47.254767 | I44: -122.7369 | L44: WGS84 | M44: -0.12192 | O44: cobble | P44: absent | Q44: poor | R44: cobble | S44: 2014_1125_S Sound out of Home.pdf
A45: 41968 | B45: Eelgrass Restoration in PS | C45: Key Peninsula-east | D45: Key Peninsula-east-PNNL-2014 Site Assessment point 13 | E45: restoration | F45: point | G45: camera | H45: 47.252983 | I45: -122.73467 | L45: WGS84 | M45: -0.48768 | O45: sand | P45: absent | Q45: good | R45: sand, good potential, some ulva | S45: 2014_1125_S Sound out of Home.pdf
...

Sheet Planting GPS Points
A1: SITE LOCATION | B1: SITE NAME | C1: planting_location_code | D1: planting_relationships | E1: YEAR | F1: HISTORICAL PRESENCE | G1: DATA TYPE | H1: WATER BODY | I1: SVMP REGION | J1: PROJECT NAME | K1: FUNDING SOURCE | L1: FUNDING SOURCE PROGRAM | M1: CONTRACT 1 | N1: CONTRACT 1 | O1: CONTRACT 2 | P1: CONTRACT 2 | Q1: CITATION | R1: ACTIVITY TYPE | S1: ACTIVITY FILTER | T1: PLANTING DATE | U1: LATITUDE | V1: LONGITUDE | W1: data_type | X1: retain_drop | Y1: DATUM | Z1: ELEVATION | AA1: PLANTING METHOD | AB1: PARALLEL SIDE | AC1: PERPENDICULAR SIDE | AD1: PLOT AREA | AE1: PLANTED AREA | AF1: EFFECTIVE AREA PLANTED | AG1: # OF PLANTING UNITS | AH1: # OF SHOOTS | AI1: PLOT SHOOT DENSITY | AJ1: PLANTED SHOOT DENSITY | AK1: DONOR SITE NAME | AL1: NOTES
F2: (source) | G2: (point, polygon, line) | M2: (b/w funding source & DNR) | N2: (DNR contract #) | O2: (b/w DNR & contractor) | P2: (DNR contract #) | R2: (test planting, large-scale planting) | S2: (test planting, large-scale planting) | T2: (YYYY-MM-DD) | U2: (dec deg) | V2: (dec deg) | Y2: (WGS84, NAD83) | Z2: (m, MLLW) | AA2: (staple, rebar, washer, burlap, turf, ?) | AB2: (m) | AC2: (m) | AD2: (m2) | AE2: (m2) | AF2: (m2) | AG2: (count of staples, rebar, etc.) | AH2: (shoots planted) | AI2: (shoots m-2 of plot area) | AJ2: (shoots m-2 of planted area)
A3: Anderson Island | B3: Amsterdam Bay - PNNL - shallow - test - 2013 | C3: =VLOOKUP(B3,Plantings!$A$2:$C$285,2,FALSE) -> AMS_shallow | D3: =VLOOKUP(B3,Plantings!$A$2:$C$285,3,FALSE) -> single | E3: 2013 | F3: Thom, RM, and L Hallum. 1990. Long‐term changes in the areal extent of tidal marshes, eelgrass meadows, and kelp forests of Puget Sound. FRI‐UW‐9008, Fisheries Research Institute, School of Fisheries, University of Washington, Seattle. Pp. 110. | G3: point | H3: Drayton Passage | I3: CPS | J3: 20% more ZM | K3: WDFW | L3: National Estuary Program | M3: 12-1117 | N3: IAA 12-316 | O3: PNNL | P3: IAA 12-317 | Q3: Vavrinec, J., A.B. Borde, R.M. Thom, S.L. Southard, J. Elster, K.D. Hall, L.M. Aston and J.L. Gaeckle. 2014. Evaluation of potential eelgrass restoration sites: methods, results, and recommendations. Prepared for the U.S. Department of Energy under contract DE-AC05-76RL01830. Pacific Northwest National Laboratory, Richland, WA. PNNL-23502. | R3: test | S3: test | T3: 41431 | U3: 47.1606 | V3: -122.72777 | W3: =VLOOKUP(B3,Plantings!$A$2:$E$285,4,FALSE) -> point | X3: =VLOOKUP(B3,Plantings!$A$2:$E$285,5,FALSE) -> retain | Y3: WGS84 | Z3: -0.9144 | AA3: staple | AB3: 6 | AC3: 6 | AD3: =AB3*AC3 -> 36 | AE3: 36 | AF3: =IF(AA3="staple",AG3*0.005,IF(AA3="rebar",AG3*0.025,IF(AA3="burlap",AG3*0.0625,IF(AA3="washer",AG3*0.0025,IF(AA3="pucks",AG3*0.00785,IF(AA3="turf",AG3*0.01,IF(AA3="",""))))))) -> 0.9 | AG3: =AH3/4 -> 180 | AH3: 720 | AI3: =IFERROR(AH3/AD3, "") -> 20 | AJ3: =IFERROR(AH3/AE3, "") -> 20 | AK3: Thompson Cove
A4: Anderson Island | B4: Amsterdam Bay - PNNL - deep - test - 2013 | C4: =VLOOKUP(B4,Plantings!$A$2:$C$285,2,FALSE) -> AMS_deep | D4: =VLOOKUP(B4,Plantings!$A$2:$C$285,3,FALSE) -> single | E4: 2013 | F4: Thom, RM, and L Hallum. 1990. Long‐term changes in the areal extent of tidal marshes, eelgrass meadows, and kelp forests of Puget Sound. FRI‐UW‐9008, Fisheries Research Institute, School of Fisheries, University of Washington, Seattle. Pp. 110. | G4: point | H4: Drayton Passage | I4: CPS | J4: 20% more ZM | K4: WDFW | L4: National Estuary Program | M4: 12-1117 | N4: IAA 12-316 | O4: PNNL | P4: IAA 12-317 | Q4: Vavrinec, J., A.B. Borde, R.M. Thom, S.L. Southard, J. Elster, K.D. Hall, L.M. Aston and J.L. Gaeckle. 2014. Evaluation of potential eelgrass restoration sites: methods, results, and recommendations. Prepared for the U.S. Department of Energy under contract DE-AC05-76RL01830. Pacific Northwest National Laboratory, Richland, WA. PNNL-23502. | R4: test | S4: test | T4: 41431 | U4: 47.160683 | V4: -122.72782 | W4: =VLOOKUP(B4,Plantings!$A$2:$E$285,4,FALSE) -> point | X4: =VLOOKUP(B4,Plantings!$A$2:$E$285,5,FALSE) -> retain | Y4: WGS84 | Z4: -1.524 | AA4: staple | AB4: 6 | AC4: 6 | AD4: =AB4*AC4 -> 36 | AE4: 36 | AF4: =IF(AA4="staple",AG4*0.005,IF(AA4="rebar",AG4*0.025,IF(AA4="burlap",AG4*0.0625,IF(AA4="washer",AG4*0.0025,IF(AA4="pucks",AG4*0.00785,IF(AA4="turf",AG4*0.01,IF(AA4="",""))))))) -> 0.9 | AG4: =AH4/4 -> 180 | AH4: 720 | AI4: =IFERROR(AH4/AD4, "") -> 20 | AJ4: =IFERROR(AH4/AE4, "") -> 20 | AK4: Thompson Cove
A5: Anderson Island | B5: Anderson Island West - PNNL - test - 2015 | C5: =VLOOKUP(B5,Plantings!$A$2:$C$285,2,FALSE) -> AND_west1 | D5: =VLOOKUP(B5,Plantings!$A$2:$C$285,3,FALSE) -> single | E5: 2015 | F5: Thom, RM, and L Hallum. 1990. Long‐term changes in the areal extent of tidal marshes, eelgrass meadows, and kelp forests of Puget Sound. FRI‐UW‐9008, Fisheries Research Institute, School of Fisheries, University of Washington, Seattle. Pp. 110. | G5: point | H5: Drayton Passage | I5: CPS | J5: Eelgrass Restoration in PS | K5: DNR | L5: Aquatic Restoration Program | O5: PNNL | P5: IAA 12-317.1 | Q5: Aston, L.A., A.B. Borde and J. Vavrinec. 2015. Final Summary Report - Eelgrass Restoration in Puget Sound Project Summary. Pacific Northwest National Laboratory, Richland, WA. PNNL-24445. | R5: test | S5: test | T5: 42062 | U5: 47.170783 | V5: -122.72888 | W5: =VLOOKUP(B5,Plantings!$A$2:$E$285,4,FALSE) -> point | X5: =VLOOKUP(B5,Plantings!$A$2:$E$285,5,FALSE) -> retain | Y5: WGS84 | Z5: -0.8 | AA5: staple | AB5: 5 | AC5: 5 | AD5: =AB5*AC5 -> 25 | AE5: 25 | AF5: =IF(AA5="staple",AG5*0.005,IF(AA5="rebar",AG5*0.025,IF(AA5="burlap",AG5*0.0625,IF(AA5="washer",AG5*0.0025,IF(AA5="pucks",AG5*0.00785,IF(AA5="turf",AG5*0.01,IF(AA5="",""))))))) -> 0.625 | AG5: =AH5/4 -> 125 | AH5: 500 | AI5: =IFERROR(AH5/AD5, "") -> 20 | AJ5: =IFERROR(AH5/AE5, "") -> 20 | AK5: Ketron Island
A6: Anderson Island | B6: Anderson Island West - PNNL - test - 2016 | C6: =VLOOKUP(B6,Plantings!$A$2:$C$285,2,FALSE) -> AND_west2 | D6: =VLOOKUP(B6,Plantings!$A$2:$C$285,3,FALSE) -> single | E6: 2016 | F6: Thom, RM, and L Hallum. 1990. Long‐term changes in the areal extent of tidal marshes, eelgrass meadows, and kelp forests of Puget Sound. FRI‐UW‐9008, Fisheries Research Institute, School of Fisheries, University of Washington, Seattle. Pp. 110. | G6: point | H6: Nisqually Reach | I6: CPS | J6: Puget Sound Eelgrass Restoration: 3 deltas | K6: USACE | L6: USACE | M6: W912DW-14-2-0009 (93-099566) | N6: IAA 15-45 | O6: PNNL | P6: 93-099661 | R6: test | S6: test | T6: 42633 | U6: 47.170933 | V6: -122.72905 | W6: =VLOOKUP(B6,Plantings!$A$2:$E$285,4,FALSE) -> point | X6: =VLOOKUP(B6,Plantings!$A$2:$E$285,5,FALSE) -> retain | Y6: WGS84 | Z6: -1.7 | AA6: rebar | AB6: 2.5 | AC6: 2.5 | AD6: =AB6*AC6 -> 6.25 | AE6: =AG6*0.25 -> 5 | AF6: =IF(AA6="staple",AG6*0.005,IF(AA6="rebar",AG6*0.025,IF(AA6="burlap",AG6*0.0625,IF(AA6="washer",AG6*0.0025,IF(AA6="pucks",AG6*0.00785,IF(AA6="turf",AG6*0.01,IF(AA6="",""))))))) -> 0.5 | AG6: 20 | AH6: 500 | AI6: =IFERROR(AH6/AD6, "") -> 80 | AJ6: =IFERROR(AH6/AE6, "") -> 100 | AK6: Sandy Point
A7: Anderson Island | B7: Anderson Island South - PNNL - test - 2016 | C7: =VLOOKUP(B7,Plantings!$A$2:$C$285,2,FALSE) -> AND_south1 | D7: =VLOOKUP(B7,Plantings!$A$2:$C$285,3,FALSE) -> single | E7: 2016 | F7: Thom, RM, and L Hallum. 1990. Long‐term changes in the areal extent of tidal marshes, eelgrass meadows, and kelp forests of Puget Sound. FRI‐UW‐9008, Fisheries Research Institute, School of Fisheries, University of Washington, Seattle. Pp. 110. | G7: point | H7: Nisqually Reach | I7: CPS | J7: Puget Sound Eelgrass Restoration: 3 deltas | K7: USACE | L7: USACE | M7: W912DW-14-2-0009 (93-099566) | N7: IAA 15-45 | O7: PNNL | P7: 93-099661 | R7: test | S7: test | T7: 42633 | U7: 47.132633 | V7: -122.71812 | W7: =VLOOKUP(B7,Plantings!$A$2:$E$285,4,FALSE) -> point | X7: =VLOOKUP(B7,Plantings!$A$2:$E$285,5,FALSE) -> retain | Y7: WGS84 | Z7: -1.9 | AA7: rebar | AB7: 2.5 | AC7: 2.5 | AD7: =AB7*AC7 -> 6.25 | AE7: =AG7*0.25 -> 5 | AF7: =IF(AA7="staple",AG7*0.005,IF(AA7="rebar",AG7*0.025,IF(AA7="burlap",AG7*0.0625,IF(AA7="washer",AG7*0.0025,IF(AA7="pucks",AG7*0.00785,IF(AA7="turf",AG7*0.01,IF(AA7="",""))))))) -> 0.5 | AG7: 20 | AH7: 500 | AI7: =IFERROR(AH7/AD7, "") -> 80 | AJ7: =IFERROR(AH7/AE7, "") -> 100 | AK7: Sandy Point | AL7: Also known as Gaeckle 3
A8: Anderson Island | B8: Anderson Island West - North - south - HC - test - 2017 | C8: =VLOOKUP(B8,Plantings!$A$2:$C$285,2,FALSE) -> AND_west_L1 | D8: =VLOOKUP(B8,Plantings!$A$2:$C$285,3,FALSE) -> single | E8: 2017 | F8: Thom, RM, and L Hallum. 1990. Long‐term changes in the areal extent of tidal marshes, eelgrass meadows, and kelp forests of Puget Sound. FRI‐UW‐9008, Fisheries Research Institute, School of Fisheries, University of Washington, Seattle. Pp. 110. | G8: line | H8: Drayton Passage | I8: CPS | J8: Eelgrass Restoration in Puget Sound | K8: WDFW | L8: National Estuary Program | M8: 14-02072 | N8: IAA 15-110 | O8: Hart Crowser | P8: SC 16-17 | Q8: Shannon, J., J. Blanchette and J. Gaeckle. 2018. Eelgrass (Zostera marina) Restoration in Puget Sound, WA. Final Restoration and Monitoring Report (12059-05) for US EPA, Hart Crowser, Edmonds, WA. Pp. 131. | R8: test | S8: test | T8: 42860 | U8: 47.18183 | V8: -122.71405 | W8: =VLOOKUP(B8,Plantings!$A$2:$E$285,4,FALSE) -> line | X8: =VLOOKUP(B8,Plantings!$A$2:$E$285,5,FALSE) -> retain | Y8: WGS84 | Z8: -1.6 | AA8: turf | AB8: 10 | AC8: 1 | AD8: =AB8*AC8 -> 10 | AE8: 6 | AF8: =IF(AA8="staple",AG8*0.005,IF(AA8="rebar",AG8*0.025,IF(AA8="burlap",AG8*0.0625,IF(AA8="washer",AG8*0.0025,IF(AA8="pucks",AG8*0.00785,IF(AA8="turf",AG8*0.01,IF(AA8="",""))))))) -> 0.87 | AG8: 87 | AH8: 869 | AI8: =IFERROR(AH8/AD8, "") -> 86.9 | AJ8: =IFERROR(AH8/AE8, "") -> 144.83333 | AK8: Rocky Bay | AL8: Referred to as 'Anderson Island West 1' in final report. Turfs plant 5-15 shoots per staple (X= ~10 shoots/staple). Estimated number of PUs at test-transplant site as 869/10 = 87.
A9: Anderson Island | B9: Anderson Island West - North - north - HC - test - 2017 | C9: =VLOOKUP(B9,Plantings!$A$2:$C$285,2,FALSE) -> AND_west_L1 | D9: =VLOOKUP(B9,Plantings!$A$2:$C$285,3,FALSE) -> single | E9: 2017 | F9: Thom, RM, and L Hallum. 1990. Long‐term changes in the areal extent of tidal marshes, eelgrass meadows, and kelp forests of Puget Sound. FRI‐UW‐9008, Fisheries Research Institute, School of Fisheries, University of Washington, Seattle. Pp. 110. | G9: line | H9: Drayton Passage | I9: CPS | J9: Eelgrass Restoration in Puget Sound | K9: WDFW | L9: National Estuary Program | M9: 14-02072 | N9: IAA 15-110 | O9: Hart Crowser | P9: SC 16-17 | Q9: Shannon, J., J. Blanchette and J. Gaeckle. 2018. Eelgrass (Zostera marina) Restoration in Puget Sound, WA. Final Restoration and Monitoring Report (12059-05) for US EPA, Hart Crowser, Edmonds, WA. Pp. 131. | R9: test | S9: -- | T9: 42860 | U9: 47.18186 | V9: -122.71403 | W9: =VLOOKUP(B9,Plantings!$A$2:$E$285,4,FALSE) -> line | X9: =VLOOKUP(B9,Plantings!$A$2:$E$285,5,FALSE) -> retain | Y9: WGS84 | AF9: =IF(AA9="staple",AG9*0.005,IF(AA9="rebar",AG9*0.025,IF(AA9="burlap",AG9*0.0625,IF(AA9="washer",AG9*0.0025,IF(AA9="pucks",AG9*0.00785,IF(AA9="turf",AG9*0.01,IF(AA9="",""))))))) | AI9: =IFERROR(AH9/AD9, "") | AJ9: =IFERROR(AH9/AE9, "")
A10: Anderson Island | B10: Anderson Island West - South - south - HC - test - 2017 | C10: =VLOOKUP(B10,Plantings!$A$2:$C$285,2,FALSE) -> AND_south_L1 | D10: =VLOOKUP(B10,Plantings!$A$2:$C$285,3,FALSE) -> single | E10: 2017 | F10: Thom, RM, and L Hallum. 1990. Long‐term changes in the areal extent of tidal marshes, eelgrass meadows, and kelp forests of Puget Sound. FRI‐UW‐9008, Fisheries Research Institute, School of Fisheries, University of Washington, Seattle. Pp. 110. | G10: line | H10: Drayton Passage | I10: CPS | J10: Eelgrass Restoration in Puget Sound | K10: WDFW | L10: National Estuary Program | M10: 14-02072 | N10: IAA 15-110 | O10: Hart Crowser | P10: SC 16-17 | Q10: Shannon, J., J. Blanchette and J. Gaeckle. 2018. Eelgrass (Zostera marina) Restoration in Puget Sound, WA. Final Restoration and Monitoring Report (12059-05) for US EPA, Hart Crowser, Edmonds, WA. Pp. 131. | R10: test | S10: test | T10: 42860 | U10: 47.1769 | V10: -122.7251 | W10: =VLOOKUP(B10,Plantings!$A$2:$E$285,4,FALSE) -> line | X10: =VLOOKUP(B10,Plantings!$A$2:$E$285,5,FALSE) -> retain | Y10: WGS84 | Z10: -1.6 | AA10: turf | AB10: 10 | AC10: 1 | AD10: =AB10*AC10 -> 10 | AE10: 6 | AF10: =IF(AA10="staple",AG10*0.005,IF(AA10="rebar",AG10*0.025,IF(AA10="burlap",AG10*0.0625,IF(AA10="washer",AG10*0.0025,IF(AA10="pucks",AG10*0.00785,IF(AA10="turf",AG10*0.01,IF(AA10="",""))))))) -> 0.87 | AG10: 87 | AH10: 869 | AI10: =IFERROR(AH10/AD10, "") -> 86.9 | AJ10: =IFERROR(AH10/AE10, "") -> 144.83333 | AK10: Rocky Bay | AL10: Referred to as 'Anderson Island West 2' in final report. Turfs plant 5-15 shoots per staple (X= ~10 shoots/staple). Estimated number of PUs at test-transplant site as 869/10 = 87.
A11: Anderson Island | B11: Anderson Island West - South - north - HC - test - 2017 | C11: =VLOOKUP(B11,Plantings!$A$2:$C$285,2,FALSE) -> AND_south_L1 | D11: =VLOOKUP(B11,Plantings!$A$2:$C$285,3,FALSE) -> single | E11: 2017 | F11: Thom, RM, and L Hallum. 1990. Long‐term changes in the areal extent of tidal marshes, eelgrass meadows, and kelp forests of Puget Sound. FRI‐UW‐9008, Fisheries Research Institute, School of Fisheries, University of Washington, Seattle. Pp. 110. | G11: line | H11: Drayton Passage | I11: CPS | J11: Eelgrass Restoration in Puget Sound | K11: WDFW | L11: National Estuary Program | M11: 14-02072 | N11: IAA 15-110 | O11: Hart Crowser | P11: SC 16-17 | Q11: Shannon, J., J. Blanchette and J. Gaeckle. 2018. Eelgrass (Zostera marina) Restoration in Puget Sound, WA. Final Restoration and Monitoring Report (12059-05) for US EPA, Hart Crowser, Edmonds, WA. Pp. 131. | R11: test | S11: -- | T11: 42860 | U11: 47.17693 | V11: -122.72505 | W11: =VLOOKUP(B11,Plantings!$A$2:$E$285,4,FALSE) -> line | X11: =VLOOKUP(B11,Plantings!$A$2:$E$285,5,FALSE) -> retain | Y11: WGS84 | AF11: =IF(AA11="staple",AG11*0.005,IF(AA11="rebar",AG11*0.025,IF(AA11="burlap",AG11*0.0625,IF(AA11="washer",AG11*0.0025,IF(AA11="pucks",AG11*0.00785,IF(AA11="turf",AG11*0.01,IF(AA11="",""))))))) | AI11: =IFERROR(AH11/AD11, "") | AJ11: =IFERROR(AH11/AE11, "")
A12: Anderson Island | B12: Anderson Island South 1 - west - HC - large - 2017 | C12: =VLOOKUP(B12,Plantings!$A$2:$C$285,2,FALSE) -> AND_south_L2 | D12: =VLOOKUP(B12,Plantings!$A$2:$C$285,3,FALSE) -> single | E12: 2017 | F12: Thom, RM, and L Hallum. 1990. Long‐term changes in the areal extent of tidal marshes, eelgrass meadows, and kelp forests of Puget Sound. FRI‐UW‐9008, Fisheries Research Institute, School of Fisheries, University of Washington, Seattle. Pp. 110. | G12: polygon | H12: Nisqually Reach | I12: CPS | J12: Eelgrass Restoration in Puget Sound | K12: WDFW | L12: National Estuary Program | M12: 14-02072 | N12: IAA 15-110 | O12: Hart Crowser | P12: SC 16-17 | Q12: Shannon, J., J. Blanchette and J. Gaeckle. 2018. Eelgrass (Zostera marina) Restoration in Puget Sound, WA. Final Restoration and Monitoring Report (12059-05) for US EPA, Hart Crowser, Edmonds, WA. Pp. 131. | R12: large scale | S12: large scale | T12: 42888 | U12: 47.13875 | V12: -122.72511 | W12: =VLOOKUP(B12,Plantings!$A$2:$E$285,4,FALSE) -> line | X12: =VLOOKUP(B12,Plantings!$A$2:$E$285,5,FALSE) -> retain | Y12: WGS84 | Z12: -1.6 | AA12: turf | AB12: 40 | AC12: 4 | AD12: =AB12*AC12 -> 160 | AE12: 155 | AF12: =IF(AA12="staple",AG12*0.005,IF(AA12="rebar",AG12*0.025,IF(AA12="burlap",AG12*0.0625,IF(AA12="washer",AG12*0.0025,IF(AA12="pucks",AG12*0.00785,IF(AA12="turf",AG12*0.01,IF(AA12="",""))))))) -> 20.5 | AG12: 2050 | AH12: 20500 | AI12: =IFERROR(AH12/AD12, "") -> 128.125 | AJ12: =IFERROR(AH12/AE12, "") -> 132.25806 | AK12: Rocky Bay | AL12: large scale area of 40 m X 4 m (160 m2). Planted with plants from Rocky Bay. Turfs plant 5-15 shoots per staple (X= ~10 shoots/staple). Estimated number of PUs at test-transplant site as 20500/10 = 2050.
A13: Anderson Island | B13: Anderson Island South 1 - east - HC - large - 2017 | C13: =VLOOKUP(B13,Plantings!$A$2:$C$285,2,FALSE) -> AND_south_L2 | D13: =VLOOKUP(B13,Plantings!$A$2:$C$285,3,FALSE) -> single | E13: 2017 | F13: Thom, RM, and L Hallum. 1990. Long‐term changes in the areal extent of tidal marshes, eelgrass meadows, and kelp forests of Puget Sound. FRI‐UW‐9008, Fisheries Research Institute, School of Fisheries, University of Washington, Seattle. Pp. 110. | G13: polygon | H13: Nisqually Reach | I13: CPS | J13: Eelgrass Restoration in Puget Sound | K13: WDFW | L13: National Estuary Program | M13: 14-02072 | N13: IAA 15-110 | O13: Hart Crowser | P13: SC 16-17 | Q13: Shannon, J., J. Blanchette and J. Gaeckle. 2018. Eelgrass (Zostera marina) Restoration in Puget Sound, WA. Final Restoration and Monitoring Report (12059-05) for US EPA, Hart Crowser, Edmonds, WA. Pp. 131. | R13: large scale | S13: -- | T13: 42888 | U13: 47.138917 | V13: -122.72556 | W13: =VLOOKUP(B13,Plantings!$A$2:$E$285,4,FALSE) -> line | X13: =VLOOKUP(B13,Plantings!$A$2:$E$285,5,FALSE) -> retain | Y13: WGS84 | AF13: =IF(AA13="staple",AG13*0.005,IF(AA13="rebar",AG13*0.025,IF(AA13="burlap",AG13*0.0625,IF(AA13="washer",AG13*0.0025,IF(AA13="pucks",AG13*0.00785,IF(AA13="turf",AG13*0.01,IF(AA13="",""))))))) | AI13: =IFERROR(AH13/AD13, "") | AJ13: =IFERROR(AH13/AE13, "")
A14: Anderson Island | B14: Anderson Island South 2 - west - HC - large - 2017 | C14: =VLOOKUP(B14,Plantings!$A$2:$C$285,2,FALSE) -> AND_south_L3 | D14: =VLOOKUP(B14,Plantings!$A$2:$C$285,3,FALSE) -> single | E14: 2017 | F14: Thom, RM, and L Hallum. 1990. Long‐term changes in the areal extent of tidal marshes, eelgrass meadows, and kelp forests of Puget Sound. FRI‐UW‐9008, Fisheries Research Institute, School of Fisheries, University of Washington, Seattle. Pp. 110. | G14: polygon | H14: Nisqually Reach | I14: CPS | J14: Eelgrass Restoration in Puget Sound | K14: WDFW | L14: National Estuary Program | M14: 14-02072 | N14: IAA 15-110 | O14: Hart Crowser | P14: SC 16-17 | Q14: Shannon, J., J. Blanchette and J. Gaeckle. 2018. Eelgrass (Zostera marina) Restoration in Puget Sound, WA. Final Restoration and Monitoring Report (12059-05) for US EPA, Hart Crowser, Edmonds, WA. Pp. 131. | R14: large scale | S14: large scale | T14: 42890 | U14: 47.13825 | V14: -122.72369 | W14: =VLOOKUP(B14,Plantings!$A$2:$E$285,4,FALSE) -> line | X14: =VLOOKUP(B14,Plantings!$A$2:$E$285,5,FALSE) -> retain | Y14: WGS84 | Z14: -1.6 | AA14: turf | AB14: 40 | AC14: 4 | AD14: =AB14*AC14 -> 160 | AE14: 160 | AF14: =IF(AA14="staple",AG14*0.005,IF(AA14="rebar",AG14*0.025,IF(AA14="burlap",AG14*0.0625,IF(AA14="washer",AG14*0.0025,IF(AA14="pucks",AG14*0.00785,IF(AA14="turf",AG14*0.01,IF(AA14="",""))))))) -> 24.83 | AG14: 2483 | AH14: 24830 | AI14: =IFERROR(AH14/AD14, "") -> 155.1875 | AJ14: =IFERROR(AH14/AE14, "") -> 155.1875 | AK14: Rocky Bay | AL14: large scale area of 40 m X 4 m (160 m2). Planted with plants from Rocky Bay. Planted with plants from Rocky Bay. Turfs plant 5-15 shoots per staple (X= ~10 shoots/staple). Estimated number of PUs at test-transplant site as 24,830/10 = 2483.
A15: Anderson Island | B15: Anderson Island South 2 - east - HC - large - 2017 | C15: =VLOOKUP(B15,Plantings!$A$2:$C$285,2,FALSE) -> AND_south_L3 | D15: =VLOOKUP(B15,Plantings!$A$2:$C$285,3,FALSE) -> single | E15: 2017 | F15: Thom, RM, and L Hallum. 1990. Long‐term changes in the areal extent of tidal marshes, eelgrass meadows, and kelp forests of Puget Sound. FRI‐UW‐9008, Fisheries Research Institute, School of Fisheries, University of Washington, Seattle. Pp. 110. | G15: polygon | H15: Nisqually Reach | I15: CPS | J15: Eelgrass Restoration in Puget Sound | K15: WDFW | L15: National Estuary Program | M15: 14-02072 | N15: IAA 15-110 | O15: Hart Crowser | P15: SC 16-17 | Q15: Shannon, J., J. Blanchette and J. Gaeckle. 2018. Eelgrass (Zostera marina) Restoration in Puget Sound, WA. Final Restoration and Monitoring Report (12059-05) for US EPA, Hart Crowser, Edmonds, WA. Pp. 131. | R15: large scale | S15: -- | T15: 42890 | U15: 47.138444 | V15: -122.72417 | W15: =VLOOKUP(B15,Plantings!$A$2:$E$285,4,FALSE) -> line | X15: =VLOOKUP(B15,Plantings!$A$2:$E$285,5,FALSE) -> retain | Y15: WGS84 | AF15: =IF(AA15="staple",AG15*0.005,IF(AA15="rebar",AG15*0.025,IF(AA15="burlap",AG15*0.0625,IF(AA15="washer",AG15*0.0025,IF(AA15="pucks",AG15*0.00785,IF(AA15="turf",AG15*0.01,IF(AA15="",""))))))) | AI15: =IFERROR(AH15/AD15, "") | AJ15: =IFERROR(AH15/AE15, "")
A16: Anderson Island | B16: Anderson Island South 3 - east - PNNL - large - 2017 | C16: =VLOOKUP(B16,Plantings!$A$2:$C$285,2,FALSE) -> AND_south_L4 | D16: =VLOOKUP(B16,Plantings!$A$2:$C$285,3,FALSE) -> single | E16: 2017 | F16: Thom, RM, and L Hallum. 1990. Long‐term changes in the areal extent of tidal marshes, eelgrass meadows, and kelp forests of Puget Sound. FRI‐UW‐9008, Fisheries Research Institute, School of Fisheries, University of Washington, Seattle. Pp. 110. | G16: line | H16: Nisqually Reach | I16: CPS | J16: Puget Sound Eelgrass Restoration: 3 deltas | K16: USACE | L16: USACE | M16: W912DW-14-2-0009 (93-099566) | N16: IAA 15-45 | O16: PNNL | P16: IAA 15-101 | R16: large scale | S16: large scale | T16: 42955 | U16: 47.132633 | V16: -122.71812 | W16: =VLOOKUP(B16,Plantings!$A$2:$E$285,4,FALSE) -> line | X16: =VLOOKUP(B16,Plantings!$A$2:$E$285,5,FALSE) -> retain | Y16: WGS84 | Z16: -1.31064 | AA16: rebar | AB16: 30 | AC16: 5 | AD16: =AB16*AC16 -> 150 | AE16: =AG16*0.25 -> 105.25 | AF16: =IF(AA16="staple",AG16*0.005,IF(AA16="rebar",AG16*0.025,IF(AA16="burlap",AG16*0.0625,IF(AA16="washer",AG16*0.0025,IF(AA16="pucks",AG16*0.00785,IF(AA16="turf",AG16*0.01,IF(AA16="",""))))))) -> 10.525 | AG16: 421 | AH16: 10525 | AI16: =IFERROR(AH16/AD16, "") -> 70.166667 | AJ16: =IFERROR(AH16/AE16, "") -> 100 | AK16: Thompson Cove | AL16: Site also known as Gaeckle 3, base line runs 320°
A17: Anderson Island | B17: Anderson Island South 3 - east - PNNL - large - 2017 | C17: =VLOOKUP(B17,Plantings!$A$2:$C$285,2,FALSE) -> AND_south_L4 | D17: =VLOOKUP(B17,Plantings!$A$2:$C$285,3,FALSE) -> single | E17: 2017 | F17: Thom, RM, and L Hallum. 1990. Long‐term changes in the areal extent of tidal marshes, eelgrass meadows, and kelp forests of Puget Sound. FRI‐UW‐9008, Fisheries Research Institute, School of Fisheries, University of Washington, Seattle. Pp. 110. | G17: line | H17: Nisqually Reach | I17: CPS | J17: Puget Sound Eelgrass Restoration: 3 deltas | K17: USACE | L17: USACE | M17: W912DW-14-2-0009 (93-099566) | N17: IAA 15-45 | O17: PNNL | P17: IAA 15-101 | R17: large scale | S17: -- | T17: 42955 | U17: 47.13238 | V17: -122.71795 | W17: =VLOOKUP(B17,Plantings!$A$2:$E$285,4,FALSE) -> line | X17: =VLOOKUP(B17,Plantings!$A$2:$E$285,5,FALSE) -> retain | Y17: WGS84 | AF17: =IF(AA17="staple",AG17*0.005,IF(AA17="rebar",AG17*0.025,IF(AA17="burlap",AG17*0.0625,IF(AA17="washer",AG17*0.0025,IF(AA17="pucks",AG17*0.00785,IF(AA17="turf",AG17*0.01,IF(AA17="",""))))))) | AI17: =IFERROR(AH17/AD17, "") | AJ17: =IFERROR(AH17/AE17, "")
A18: Anderson Island | B18: Amsterdam Bay - PNNL - deeper - test - 2020 | C18: =VLOOKUP(B18,Plantings!$A$2:$C$285,2,FALSE) -> AMS_deeper | D18: =VLOOKUP(B18,Plantings!$A$2:$C$285,3,FALSE) -> single | E18: 2020 | F18: Thom, RM, and L Hallum. 1990. Long‐term changes in the areal extent of tidal marshes, eelgrass meadows, and kelp forests of Puget Sound. FRI‐UW‐9008, Fisheries Research Institute, School of Fisheries, University of Washington, Seattle. Pp. 110. | G18: point | H18: Drayton Passage | I18: CPS | J18: Eelgrass Recovery in PS | K18: USACE | L18: USACE | M18: W912DW-14-2-0009 (93-099566) | N18: IAA 15-45 | O18: PNNL | R18: test | S18: test | T18: 44012 | U18: 47.160376 | V18: -122.72772 | W18: =VLOOKUP(B18,Plantings!$A$2:$E$285,4,FALSE) -> point | X18: =VLOOKUP(B18,Plantings!$A$2:$E$285,5,FALSE) -> retain | Y18: WGS84 | Z18: -1.1 | AA18: rebar | AB18: 2.5 | AC18: 2.5 | AD18: =AB18*AC18 -> 6.25 | AE18: =AG18*0.25 -> 4.75 | AF18: =IF(AA18="staple",AG18*0.005,IF(AA18="rebar",AG18*0.025,IF(AA18="burlap",AG18*0.0625,IF(AA18="washer",AG18*0.0025,IF(AA18="pucks",AG18*0.00785,IF(AA18="turf",AG18*0.01,IF(AA18="",""))))))) -> 0.475 | AG18: 19 | AH18: 475 | AI18: =IFERROR(AH18/AD18, "") -> 76 | AJ18: =IFERROR(AH18/AE18, "") -> 100 | AK18: Anderson Island | AL18: 180 deg az, sandy with gravel some wispy ulva
A19: Anderson Island | B19: Anderson Island West - PNNL - test - 2020 | C19: =VLOOKUP(B19,Plantings!$A$2:$C$285,2,FALSE) -> AND_west3 | D19: =VLOOKUP(B19,Plantings!$A$2:$C$285,3,FALSE) -> single | E19: 2020 | F19: Thom, RM, and L Hallum. 1990. Long‐term changes in the areal extent of tidal marshes, eelgrass meadows, and kelp forests of Puget Sound. FRI‐UW‐9008, Fisheries Research Institute, School of Fisheries, University of Washington, Seattle. Pp. 110. | G19: point | H19: Drayton Passage | I19: CPS | J19: Eelgrass Recovery in PS | K19: USACE | L19: USACE | M19: W912DW-14-2-0009 (93-099566) | N19: IAA 15-45 | O19: PNNL | R19: test | S19: test | T19: 44013 | U19: 47.172138 | V19: -122.72795 | W19: =VLOOKUP(B19,Plantings!$A$2:$E$285,4,FALSE) -> point | X19: =VLOOKUP(B19,Plantings!$A$2:$E$285,5,FALSE) -> retain | Y19: WGS84 | Z19: -1.2 | AA19: rebar | AB19: 3 | AC19: 2.5 | AD19: =AB19*AC19 -> 7.5 | AE19: =AG19*0.25 -> 6.25 | AF19: =IF(AA19="staple",AG19*0.005,IF(AA19="rebar",AG19*0.025,IF(AA19="burlap",AG19*0.0625,IF(AA19="washer",AG19*0.0025,IF(AA19="pucks",AG19*0.00785,IF(AA19="turf",AG19*0.01,IF(AA19="",""))))))) -> 0.625 | AG19: 25 | AH19: 625 | AI19: =IFERROR(AH19/AD19, "") -> 83.333333 | AJ19: =IFERROR(AH19/AE19, "") -> 100 | AK19: Anderson Island | AL19: 180deg az, sandy with little bit of ulva
A20: Anderson Island | B20: Anderson Island Northwest - PNNL - test - 2020 | C20: =VLOOKUP(B20,Plantings!$A$2:$C$285,2,FALSE) -> AND_nw1 | D20: =VLOOKUP(B20,Plantings!$A$2:$C$285,3,FALSE) -> single | E20: 2020 | F20: Thom, RM, and L Hallum. 1990. Long‐term changes in the areal extent of tidal marshes, eelgrass meadows, and kelp forests of Puget Sound. FRI‐UW‐9008, Fisheries Research Institute, School of Fisheries, University of Washington, Seattle. Pp. 110. | G20: point | H20: Drayton Passage | I20: CPS | J20: Eelgrass Recovery in PS | K20: USACE | L20: USACE | M20: W912DW-14-2-0009 (93-099566) | N20: IAA 15-45 | O20: PNNL | R20: test | S20: test | T20: 44012 | U20: 47.1821 | V20: -122.71379 | W20: =VLOOKUP(B20,Plantings!$A$2:$E$285,4,FALSE) -> point | X20: =VLOOKUP(B20,Plantings!$A$2:$E$285,5,FALSE) -> retain | Y20: WGS84 | Z20: -1.3 | AA20: rebar | AB20: 2.5 | AC20: 2.5 | AD20: =AB20*AC20 -> 6.25 | AE20: =AG20*0.25 -> 5 | AF20: =IF(AA20="staple",AG20*0.005,IF(AA20="rebar",AG20*0.025,IF(AA20="burlap",AG20*0.0625,IF(AA20="washer",AG20*0.0025,IF(AA20="pucks",AG20*0.00785,IF(AA20="turf",AG20*0.01,IF(AA20="",""))))))) -> 0.5 | AG20: 20 | AH20: 500 | AI20: =IFERROR(AH20/AD20, "") -> 80 | AJ20: =IFERROR(AH20/AE20, "") -> 100 | AK20: Anderson Island | AL20: 170deg az, sandy with non-attached ulva
A21: Anderson Island | B21: Anderson Island South 1 - west - test - 2021 | C21: =VLOOKUP(B21,Plantings!$A$2:$C$285,2,FALSE) -> AND_west4 | D21: =VLOOKUP(B21,Plantings!$A$2:$C$285,3,FALSE) -> single | E21: 2021 | R21: test | S21: test | T21: 44369 | W21: =VLOOKUP(B21,Plantings!$A$2:$E$285,4,FALSE) -> point | X21: =VLOOKUP(B21,Plantings!$A$2:$E$285,5,FALSE) -> retain | Y21: WGS84 | Z21: -1.5 | AA21: rebar | AB21: 3.5 | AC21: 0.5 | AD21: =AB21*AC21 -> 1.75 | AE21: =AG21*0.25 -> 2.25 | AF21: =IF(AA21="staple",AG21*0.005,IF(AA21="rebar",AG21*0.025,IF(AA21="burlap",AG21*0.0625,IF(AA21="washer",AG21*0.0025,IF(AA21="pucks",AG21*0.00785,IF(AA21="turf",AG21*0.01,IF(AA21="",""))))))) -> 0.225 | AG21: 9 | AH21: 135 | AI21: =IFERROR(AH21/AD21, "") -> 77.142857 | AJ21: =IFERROR(AH21/AE21, "") -> 60 | AK21: DuPont Wharf
A22: Anderson Island | B22: Anderson Island South 2 - west - test - 2021 | C22: =VLOOKUP(B22,Plantings!$A$2:$C$285,2,FALSE) -> AND_west5 | D22: =VLOOKUP(B22,Plantings!$A$2:$C$285,3,FALSE) -> single | E22: 2021 | R22: test | S22: test | T22: 44372 | W22: =VLOOKUP(B22,Plantings!$A$2:$E$285,4,FALSE) -> point | X22: =VLOOKUP(B22,Plantings!$A$2:$E$285,5,FALSE) -> retain | Y22: WGS84 | Z22: -1.5 | AA22: rebar | AB22: 3.5 | AC22: 0.5 | AD22: =AB22*AC22 -> 1.75 | AE22: =AG22*0.25 -> 2.25 | AF22: =IF(AA22="staple",AG22*0.005,IF(AA22="rebar",AG22*0.025,IF(AA22="burlap",AG22*0.0625,IF(AA22="washer",AG22*0.0025,IF(AA22="pucks",AG22*0.00785,IF(AA22="turf",AG22*0.01,IF(AA22="",""))))))) -> 0.225 | AG22: 9 | AH22: 135 | AI22: =IFERROR(AH22/AD22, "") -> 77.142857 | AJ22: =IFERROR(AH22/AE22, "") -> 60 | AK22: DuPont Wharf
A23: Anderson Island | B23: Anderson Island South 3 - west - test - 2021 | C23: =VLOOKUP(B23,Plantings!$A$2:$C$285,2,FALSE) -> AND_west6 | D23: =VLOOKUP(B23,Plantings!$A$2:$C$285,3,FALSE) -> single | E23: 2021 | R23: test | S23: test | T23: 44372 | W23: =VLOOKUP(B23,Plantings!$A$2:$E$285,4,FALSE) -> point | X23: =VLOOKUP(B23,Plantings!$A$2:$E$285,5,FALSE) -> retain | Y23: WGS84 | Z23: -1.5 | AA23: rebar | AB23: 3.5 | AC23: 0.5 | AD23: =AB23*AC23 -> 1.75 | AE23: =AG23*0.25 -> 2.25 | AF23: =IF(AA23="staple",AG23*0.005,IF(AA23="rebar",AG23*0.025,IF(AA23="burlap",AG23*0.0625,IF(AA23="washer",AG23*0.0025,IF(AA23="pucks",AG23*0.00785,IF(AA23="turf",AG23*0.01,IF(AA23="",""))))))) -> 0.225 | AG23: 9 | AH23: 135 | AI23: =IFERROR(AH23/AD23, "") -> 77.142857 | AJ23: =IFERROR(AH23/AE23, "") -> 60 | AK23: DuPont Wharf
A24: Anderson Island | B24: Anderson Island - Carlson Bay SE - DNR - test 1 - 2023 | C24: =VLOOKUP(B24,Plantings!$A$2:$C$285,2,FALSE) -> AND_se1 | D24: =VLOOKUP(B24,Plantings!$A$2:$C$285,3,FALSE) -> single | E24: 2023 | G24: point | H24: Case Inlet | I24: CPS | R24: test | S24: test | T24: 45082 | U24: 47.14154 | V24: -122.73026 | W24: =VLOOKUP(B24,Plantings!$A$2:$E$285,4,FALSE) -> point | X24: =VLOOKUP(B24,Plantings!$A$2:$E$285,5,FALSE) -> retain | Y24: WGS84 | Z24: -1.5 | AA24: rebar | AB24: 1.5 | AC24: 0.5 | AD24: =AB24*AC24 -> 0.75 | AE24: =AG24*0.25 -> 2.25 | AF24: =IF(AA24="staple",AG24*0.005,IF(AA24="rebar",AG24*0.025,IF(AA24="burlap",AG24*0.0625,IF(AA24="washer",AG24*0.0025,IF(AA24="pucks",AG24*0.00785,IF(AA24="turf",AG24*0.01,IF(AA24="TERFS",AG24*0.25,IF(AA24="","")))))))) -> 0.225 | AG24: 9 | AH24: 150 | AI24: =IFERROR(AH24/AD24, "") -> 200 | AJ24: =IFERROR(AH24/AE24, "") -> 66.666667 | AK24: DuPont Wharf
A25: Blind Bay | B25: Blind Bay - DNR - test - 2020 | C25: =VLOOKUP(B25,Plantings!$A$2:$C$285,2,FALSE) -> BB_test_1 | D25: =VLOOKUP(B25,Plantings!$A$2:$C$285,3,FALSE) -> single | E25: 2020 | F25: SVMP | G25: line | H25: Blind Bay | I25: SJS | J25: Eelgrass Recovery in the San Juan Islands | K25: DNR | L25: SRFB - 19-1402 | R25: test | S25: test | T25: 44045 | U25: 48.57816 | V25: -122.94099 | W25: =VLOOKUP(B25,Plantings!$A$2:$E$285,4,FALSE) -> line | X25: =VLOOKUP(B25,Plantings!$A$2:$E$285,5,FALSE) -> retain | Y25: WGS84 | Z25: -1.7 | AA25: rebar | AB25: 14 | AC25: 1 | AD25: =AB25*AC25 -> 14 | AE25: =AG25*0.25 -> 4 | AF25: 0.4 | AG25: 16 | AH25: 320 | AI25: =IFERROR(AH25/AD25, "") -> 22.857143 | AJ25: =IFERROR(AH25/AE25, "") -> 80 | AK25: Dumas Bay | AL25: GPS marks the 0 m helical anchor. Another helical is set at 14 m (48.57810 -122.94094). Planting started at 2 m and ended at 10 m to keep transplants 2 m away from helicals at the end of the 14 m transect. Eelgrass harvested from the Shannon Point Marine Center mesocosms on 31 Jul 2020.
A26: Blind Bay | B26: Blind Bay - DNR - test - 2020 | C26: =VLOOKUP(B26,Plantings!$A$2:$C$285,2,FALSE) -> BB_test_1 | D26: =VLOOKUP(B26,Plantings!$A$2:$C$285,3,FALSE) -> single | E26: 2020 | F26: SVMP | G26: line | H26: Blind Bay | I26: SJS | J26: Eelgrass Recovery in the San Juan Islands | K26: DNR | L26: SRFB - 19-1402 | R26: test | S26: test | T26: 44045 | U26: 48.57816 | V26: -122.94099 | W26: =VLOOKUP(B26,Plantings!$A$2:$E$285,4,FALSE) -> line | X26: =VLOOKUP(B26,Plantings!$A$2:$E$285,5,FALSE) -> retain | Y26: WGS84 | Z26: -1.7 | AA26: rebar | AB26: 14 | AC26: 1 | AD26: =AB26*AC26 -> 14 | AE26: =AG26*0.25 -> 0.75 | AF26: 0.075 | AG26: 3 | AH26: 60 | AI26: =IFERROR(AH26/AD26, "") -> 4.2857143 | AJ26: =IFERROR(AH26/AE26, "") -> 80 | AK26: Fay Bainbridge | AL26: GPS marks the 0 m helical anchor. Another helical is set at 14 m (48.57810 -122.94094). Planting started at 2 m and ended at 10 m to keep transplants 2 m away from helicals at the end of the 14 m transect. Eelgrass harvested from the Shannon Point Marine Center mesocosms on 31 Jul 2020.
A27: Blind Bay | B27: Blind Bay - DNR - test - 2020 | C27: =VLOOKUP(B27,Plantings!$A$2:$C$285,2,FALSE) -> BB_test_1 | D27: =VLOOKUP(B27,Plantings!$A$2:$C$285,3,FALSE) -> single | E27: 2020 | F27: SVMP | G27: line | H27: Blind Bay | I27: SJS | J27: Eelgrass Recovery in the San Juan Islands | K27: DNR | L27: SRFB - 19-1402 | R27: test | S27: test | T27: 44045 | U27: 48.57816 | V27: -122.94099 | W27: =VLOOKUP(B27,Plantings!$A$2:$E$285,4,FALSE) -> line | X27: =VLOOKUP(B27,Plantings!$A$2:$E$285,5,FALSE) -> retain | Y27: WGS84 | Z27: -1.7 | AA27: rebar | AB27: 14 | AC27: 1 | AD27: =AB27*AC27 -> 14 | AE27: =AG27*0.25 -> 2.25 | AF27: 0.225 | AG27: 9 | AH27: 135 | AI27: =IFERROR(AH27/AD27, "") -> 9.6428571 | AJ27: =IFERROR(AH27/AE27, "") -> 60 | AK27: Henry Island | AL27: GPS marks the 0 m helical anchor. Another helical is set at 14 m (48.57810 -122.94094). Planting started at 2 m and ended at 10 m to keep transplants 2 m away from helicals at the end of the 14 m transect. Eelgrass harvested from the Pacific Northwest National Laboratory mesocosms on 31 July 2020.
A28: Blind Bay | B28: Blind Bay - DNR - test - 2020 | C28: =VLOOKUP(B28,Plantings!$A$2:$C$285,2,FALSE) -> BB_test_1 | D28: =VLOOKUP(B28,Plantings!$A$2:$C$285,3,FALSE) -> single | E28: 2020 | F28: SVMP | G28: line | H28: Blind Bay | I28: SJS | J28: Eelgrass Recovery in the San Juan Islands | K28: DNR | L28: SRFB - 19-1402 | R28: test | S28: test | T28: 44045 | U28: 48.57816 | V28: -122.94099 | W28: =VLOOKUP(B28,Plantings!$A$2:$E$285,4,FALSE) -> line | X28: =VLOOKUP(B28,Plantings!$A$2:$E$285,5,FALSE) -> retain | Y28: WGS84 | Z28: -1.7 | AA28: rebar | AB28: 14 | AC28: 1 | AD28: =AB28*AC28 -> 14 | AE28: =AG28*0.25 -> 3.75 | AF28: 0.375 | AG28: 15 | AH28: 210 | AI28: =IFERROR(AH28/AD28, "") -> 15 | AJ28: =IFERROR(AH28/AE28, "") -> 56 | AK28: Ship Harbor | AL28: GPS marks the 0 m helical anchor. Another helical is set at 14 m (48.57810 -122.94094). Planting started at 2 m and ended at 10 m to keep transplants 2 m away from helicals at the end of the 14 m transect. Eelgrass harvested from the Shannon Point Marine Center mesocosms on 31 Jul 2020.
A29: Blind Bay | B29: Blind Bay - DNR - test - 2020 | C29: =VLOOKUP(B29,Plantings!$A$2:$C$285,2,FALSE) -> BB_test_1 | D29: =VLOOKUP(B29,Plantings!$A$2:$C$285,3,FALSE) -> single | E29: 2020 | F29: SVMP | G29: line | H29: Blind Bay | I29: SJS | J29: Eelgrass Recovery in the San Juan Islands | K29: DNR | L29: SRFB - 19-1402 | R29: test | S29: test | T29: 44045 | U29: 48.57816 | V29: -122.94099 | W29: =VLOOKUP(B29,Plantings!$A$2:$E$285,4,FALSE) -> line | X29: =VLOOKUP(B29,Plantings!$A$2:$E$285,5,FALSE) -> retain | Y29: WGS84 | Z29: -1.7 | AA29: rebar | AB29: 14 | AC29: 1 | AD29: =AB29*AC29 -> 14 | AE29: =AG29*0.25 -> 1.75 | AF29: 0.175 | AG29: 7 | AH29: 175 | AI29: =IFERROR(AH29/AD29, "") -> 12.5 | AJ29: =IFERROR(AH29/AE29, "") -> 100 | AK29: Mixed | AL29: GPS marks the 0 m helical anchor. Another helical is set at 14 m (48.57810 -122.94094). Planting started at 2 m and ended at 10 m to keep transplants 2 m away from helicals at the end of the 14 m transect. Eelgrass harvested from the Shannon Point Marine Center mesocosms on 31 Jul 2020.
A30: Chico Bay | B30: Chico Bay - PNNL - test - 2015 | C30: =VLOOKUP(B30,Plantings!$A$2:$C$285,2,FALSE) -> CHC | D30: =VLOOKUP(B30,Plantings!$A$2:$C$285,3,FALSE) -> single | E30: 2015 | G30: point | H30: Dyes Inlet | I30: CPS | J30: Eelgrass Restoration in PS | K30: DNR | L30: Aquatic Restoration Program | O30: PNNL | P30: IAA 12-317.1 | Q30: Aston, L.A., A.B. Borde and J. Vavrinec. 2015. Final Summary Report - Eelgrass Restoration in Puget Sound Project Summary. Pacific Northwest National Laboratory, Richland, WA. PNNL-24445. | R30: test | S30: test | T30: 42053 | U30: 47.606483 | V30: -122.69918 | W30: =VLOOKUP(B30,Plantings!$A$2:$E$285,4,FALSE) -> point | X30: =VLOOKUP(B30,Plantings!$A$2:$E$285,5,FALSE) -> retain | Y30: WGS84 | Z30: -0.85344 | AA30: staple | AB30: 5 | AC30: 5 | AD30: =AB30*AC30 -> 25 | AE30: 25 | AF30: =IF(AA30="staple",AG30*0.005,IF(AA30="rebar",AG30*0.025,IF(AA30="burlap",AG30*0.0625,IF(AA30="washer",AG30*0.0025,IF(AA30="pucks",AG30*0.00785,IF(AA30="turf",AG30*0.01,IF(AA30="",""))))))) -> 0.625 | AG30: =AH30/4 -> 125 | AH30: 500 | AI30: =IFERROR(AH30/AD30, "") -> 20 | AJ30: =IFERROR(AH30/AE30, "") -> 20 | AK30: Creosote Point
